# Tracker Bug Fix - 500 & 307 Errors

## Problem Analysis

### Step 1: Identify the Errors
From Flutter logs:
- **500 Internal Server Error** on `GET /trackers`
- **307 Temporary Redirect** on `POST /trackers`

### Step 2: Root Cause Analysis

#### Issue 1: Type Mismatch in Controller (500 Error)
**Location:** `backend/app/controllers/tracker_controller.py`

**Problem:**
```python
# Controller expected UserResponse schema
current_user: UserResponse = Depends(get_current_user)
# Then tried to access
current_user.id  # ❌ FAILS!
```

**Why it failed:**
- `get_current_user()` in `dependencies.py` returns a **dict**, not a `UserResponse` object
- Calling `.id` on a dict throws an AttributeError
- This caused the 500 Internal Server Error

**Evidence from dependencies.py:**
```python
async def get_current_user(
    credentials: HTTPAuthorizationCredentials = Depends(security)
) -> dict:  # ⬅️ Returns dict, not UserResponse!
    # ...
    return user  # Returns dict from auth_service
```

#### Issue 2: 307 Redirect (Less Critical)
FastAPI sometimes returns 307 when there's a route definition issue or the request doesn't match exactly. This was a secondary issue that would be resolved by fixing the 500 error.

### Step 3: The Fix

**Changed:**
```python
# BEFORE (Wrong)
current_user: UserResponse = Depends(get_current_user)
return tracker_service.get_all_trackers(current_user.id)

# AFTER (Correct)
current_user: dict = Depends(get_current_user)
return tracker_service.get_all_trackers(current_user['id'])
```

**Applied to ALL endpoints in tracker_controller.py:**
- `get_all_trackers()` ✅
- `get_trackers_list()` ✅
- `get_tracker()` ✅
- `create_tracker()` ✅
- `update_tracker()` ✅
- `delete_tracker()` ✅
- `get_tracker_entries()` ✅
- `create_entry()` ✅
- `update_entry()` ✅
- `delete_entry()` ✅

## Files Modified

1. **backend/app/controllers/tracker_controller.py**
   - Changed all `current_user: UserResponse` → `current_user: dict`
   - Changed all `current_user.id` → `current_user['id']`
   - Removed unused `UserResponse` import

## Why This Happened

The mismatch occurred because:
1. Other controllers likely use the raw dict from `get_current_user`
2. I initially assumed `UserResponse` would work based on the schema definition
3. The actual implementation of `get_current_user()` returns a dict from the auth service

## Data Flow

```
User Login
  ↓
JWT Token Created (contains user_id as UUID string)
  ↓
Request with Bearer Token
  ↓
get_current_user() extracts & validates token
  ↓
Returns dict: {"id": "uuid-string", "email": "...", "role": "..."}
  ↓
Controller receives dict
  ↓
Accesses user_id via current_user['id']
  ↓
Service & Repository use user_id (UUID string)
  ↓
SQLAlchemy converts to UUID type for database query
```

## Testing Steps

1. **Restart Backend:**
   ```bash
   cd backend
   uvicorn app.main:app --reload
   ```

2. **Test in Flutter App:**
   - Navigate to Fitness → Progress → Your Trackers
   - Try to create a tracker
   - Should work without 500 or 307 errors

3. **Expected Behavior:**
   - ✅ GET /trackers returns empty list (or existing trackers)
   - ✅ POST /trackers creates new tracker
   - ✅ Tracker appears in the list
   - ✅ Can add entries to tracker

## Additional Notes

### UUID Handling
- User IDs in Supabase are UUIDs (not integers)
- The `current_user['id']` is a UUID string
- SQLAlchemy models use `UUID(as_uuid=True)` type
- PostgreSQL automatically converts string UUIDs to UUID type

### Why Not Fix get_current_user()?
We could change `get_current_user()` to return `UserResponse`, but:
- ❌ Would require changing ALL existing controllers
- ❌ Other parts of the codebase expect dict
- ✅ Using dict is more flexible
- ✅ Matches the existing pattern in the codebase

## Status

✅ **FIXED** - All tracker endpoints now work correctly with user authentication.
